Workbook

Sheet Template RSL
A1: TENDÊNCIAS E DESAFIOS EM SI - ESTRUTURAÇÃO DA INVESTIGAÇÃO SISTEMÁTICA | Y1: //
A2: Parte 1: Planejamento | C2: Comentários do professor
A3: Integrantes do time: | B3: Luiza Trigueiro, Giovanna Clócate, Antonio Carolino, Beatriz Mergulhão, Mateus Ribeiro, Luiz Miguel Gonzaga | Y3: //////////////////////////////////////
A4: Tema de pesquisa: | B4: Desenvolvimento e uso de agentes de IA para tomada de decisão e automação em operações de atendimento ao cliente (triagem e roteamento de tickets, resposta assistida/copilot, priorização por SLA, escalonamento, sumarização e registro no CRM, QA/compliance de conversas e pós-atendimento (NPS/retensão)), considerando técnicas (LLMs, MAS, RL), processo de desenvolvimento e personalização por políticas e segmentos. | Y4: /
A5: Objetivos da pesquisa: | B5: 1. Analisar a eficácia da implementação de agentes de IA em processos de tomada de decisão e automação de tarefas em organizações de médio porte. 2. Investigar como os agentes de IA impactam a estrutura de trabalho, considerando requalificação de colaboradores, produtividade e integração tecnológica. 3. Propor diretrizes e boas práticas para o desenvolvimento e adoção de agentes de IA de forma ética, eficiente e personalizada.
A6: Motivação/Justificativa: | B6: 1. Agentes de IA são cruciais para a otimização de custos, aumento da velocidade e precisão na tomada de decisão, e para a liberação de colaboradores para tarefas mais estratégicas. 2. O uso de IA em organizações levanta questões complexas, como a confiabilidade dos agentes (o problema da "caixa-preta"), a necessidade de ética e compliance nos processos automatizados, e o desafio da integração com sistemas legados. Sua pesquisa pode ajudar a mitigar esses riscos. 3. O mercado precisa de diretrizes práticas sobre como migrar do piloto de IA para a implementação em escala (em toda a organização) de forma eficaz. Seus resultados podem fornecer insights valiosos sobre melhores práticas, ferramentas ou estratégias de gestão dessa tecnologia.
A7: Artigos referência (título e link): | B7: Artificial Intelligence in Decision-making: Literature Review ( https://www.researchgate.net/publication/389628330_Artificial_Intelligence_in_Decision-making_Literature_Review?enrichId=rgreq-006d8c151c452875c7f4ea9c2f54702f-XXX&enrichSource=Y292ZXJQYWdlOzM4OTYyODMzMDtBUzoxMTQzMTI4MTMxNDI4MTkxNkAxNzQxMjk0Nzc4ODM5&el=1_x_3 ) , Nazmiye Guler, Samuel N. Kirshner, Richard Vidgen, A literature review of artificial intelligence research in business and management using machine learning and ChatGPT, Data and Information Management, Volume 8, Issue 3, 2024, 100076, ISSN 2543-9251, https://doi.org/10.1016/j.dim.2024.100076. (https://www.sciencedirect.com/science/article/pii/S2543925124000123) Autonomous AI Agents Transforming Enterprise Operations: From Static Automation to Intelligent Decision-Making Systems Maurya Priyadarshi Manipal Institute of Technology, Manipal University, India https://sarcouncil.com/download-article/SJMD-199-2025-863-870.pdf
A8: Título e link da 1 revisão selecionada | B8: Artificial Intelligence in Decision-making: Literature Review ( https://www.researchgate.net/publication/389628330_Artificial_Intelligence_in_Decision-making_Literature_Review?enrichId=rgreq-006d8c151c452875c7f4ea9c2f54702f-XXX&enrichSource=Y292ZXJQYWdlOzM4OTYyODMzMDtBUzoxMTQzMTI4MTMxNDI4MTkxNkAxNzQxMjk0Nzc4ODM5&el=1_x_3 ) Semelhanças: O foco central de ambas é o uso de agentes de IA para tomada de decisão, focando na otimização de processos e aumento da eficiência. Diferenças: O artigo se concentra mais em uma visão geral dos impactos da IA em várias áreas de tomada de decisão, analisando esse aspecto de forma mais ampla, enquanto a proposta do grupo foca especificamente nas organizações de médio porte e nos desafios da automação de tarefas repetitivas por agentes de IA
A10: Título e link da 2 revisão selecionada | B10: Quais as semelhanças e diferenças da 2 revisão com a revisão a ser desenvolvida pelo grupo? A literature review of artificial intelligence research in business and management using machine learning and ChatGPT Nazmiye Guler, Samuel N. Kirshner * University of New South Wales Business School, Sydney, 2052, Australia Richard Vidgen University of New South Wales Business School, Sydney, 2052, Australia University of Hull, School of Management, Hull, HU6 7RX, UK https://www.sciencedirect.com/science/article/pii/S2543925124000123 Semelhanças: Ambos os artigos abordam a aplicação de inteligência artificial em contextos organizacionais, com foco em autonomia e tomada de decisão. Ambos reconhecem o impacto potencial da IA em otimizar operações e aumentar a eficiência, e discutem a necessidade de estruturas de governança para garantir a eficácia e segurança no uso de IA. Ambos também lidam com avanços tecnológicos, como modelos de linguagem, no desenvolvimento de sistemas de IA autônomos. Diferenças: O artigo de Priyadarshi foca especificamente em agentes de IA autônomos, detalhando como eles evoluem da automação estática para sistemas inteligentes de tomada de decisão, com arquiteturas complexas e exemplos práticos em diversas áreas de operação empresarial. Já o artigo sobre AI em pesquisa de negócios e gestão utiliza técnicas de aprendizado de máquina para realizar revisões de literatura computacionais, abordando temas amplos como impacto da IA nas organizações e utilizando ferramentas como o ChatGPT para análise e rotulação de tópicos em grandes volumes de pesquisa. Essa comparação pode ajudar a destacar os aspectos práticos de implementação de IA no artigo de Priyadarshi, enquanto o artigo de Guler et al. oferece uma visão macro sobre como as tecnologias de IA estão sendo exploradas na literatura de negócios e gestão.
A11: Título e link da 3 revisão selecionada | B11: Quais as semelhanças e diferenças da 3 revisão com a revisão a ser desenvolvida pelo grupo? Autonomous AI Agents Transforming Enterprise Operations: From Static Automation to Intelligent Decision-Making Systems Maurya Priyadarshi Manipal Institute of Technology, Manipal University, India https://sarcouncil.com/download-article/SJMD-199-2025-863-870.pdf Semelhanças: Tanto a revisão de Priyadarshi (2025) quanto a pesquisa do grupo tratam do uso de agentes de IA para automação de tarefas e tomada de decisão em organizações, destacando ganhos de eficiência, redução de custos e aumento da produtividade, além de reconhecerem desafios como confiabilidade, segurança, compliance e impactos no trabalho humano. No entanto, enquanto o artigo internacional tem um foco mais técnico e abrangente, detalhando arquiteturas, frameworks (como LangChain, Microsoft Copilot e Relevance AI) e múltiplos casos práticos em áreas como atendimento ao cliente, operações de TI e vendas, a revisão do grupo concentra-se em organizações de médio porte, analisando a eficácia e os desafios da implementação de agentes de IA especificamente em tarefas repetitivas e propondo metodologias de adoção. Assim, enquanto o artigo mapeia estratégias globais e ferramentas de larga escala, a pesquisa do grupo se dedica mais aos impactos organizacionais, à realocação de pessoas e às diretrizes de uso em contextos mais restritos.
A12: Questão central de pesquisa: | B12: Como a implementação de agentes de IA em operações de atendimento ao cliente pode melhorar a eficiência, a produtividade e a qualidade do serviço em organizações de médio porte, considerando os desafios de integração tecnológica, as mudanças na estrutura de trabalho e os impactos na experiência dos colaboradores e dos clientes?
A13: Questões secundárias: | B13: Como os agentes de IA influenciam a alocação e redistribuição de tarefas em equipes de atendimento ao cliente, e de que forma isso afeta a gestão de pessoal nas organizações de médio porte? Quais são as implicações éticas e operacionais do uso de agentes de IA para automação de decisões e interações com clientes, e como essas questões podem ser monitoradas e mitigadas? Como a adoção de agentes de IA altera as competências e habilidades exigidas dos colaboradores em operações de atendimento, especialmente em relação à interpretação, supervisão e colaboração com sistemas autônomos?
A14: Método: | B14: Revisão sistemática
A15: RESULTADO ESPERADO PARTE 1: | B15: Planejamento da pesquisa, definindo tema, objetivos, motivação, questões de pesquisa, fundamentados por ao menos 3 artigos de referência.
E51: /

Sheet Página28

Sheet Fontes de pesquisa
A2: Principais Bases de Pesquisa
A4: Scopus | B4: Tutorial Scopus - Busca Avançada: https://www.youtube.com/watch?v=tmchre5JjFA
B5: Exemplo simples de busca avançada: https://www.youtube.com/watch?v=MdUadNWrS_8
A7: ACM | B7: Navegando na ACM Library: https://www.youtube.com/watch?v=zUHF4w-6nhc
B8: Exemplo simples de busca avançada: https://www.youtube.com/watch?v=_QtrHrHOlFg
A10: IEEE | B10: Tutorial IEEExplore for RSL - https://www.youtube.com/watch?v=_i6vIjHGh0I
B11: Exemplo simples de busca avançada: https://www.youtube.com/watch?v=C-LXhuLCZdQ
A13: Outras bases: Springer, Science Direct, Emerald, AIS

Sheet Exemplo 1 - Total Experience
A1: TENDÊNCIAS E DESAFIOS EM SI - ESTRUTURAÇÃO DA INVESTIGAÇÃO SISTEMÁTICA
A2: Parte 1: Planejamento
A3: Integrantes do time:
A4: Tema de pesquisa: | B4: Total experience e o impacto em como os produtos/serviços estão sendo construídos
A5: Objetivos da pesquisa: | B5: Entender os impactos do total experience nos serviços/produtos ao longo do tempo Entender quais são as principais aplicações do total experience em casos reais
A6: Motivação/Justificativa: | B6: Tendência estratégica do ano de 2021 (Gartner) Mudanças dos produtos e serviços no pós-pandemia Há uma mudança gradual do consumo de commodities, que além de bens/serviços, são vistos como experiências. A quarta onda na progressão econômica trouxe o surgimento de uma nova economia: “A economia da experiência” (Jain et al., 2016, Journal of Service Theory and Practice, Vol. 27 Issue: 3, p. 642) Essencial para a sobrevivência no competitivo ambiente de e-commerce de hoje, onde o concorrente é apenas um clique de distância; Significa que as empresas precisam encontrar maneiras de oferecer aos clientes uma experiência única, muito mais do que preços baixos (BILGIHAN, 2016, International Journal of Quality and Service Sciences p. 102)
A7: Artigos referência (título e link): | B7: Client-led Design: A Systemic Approach to Information Systems Definition e-Government information systems: Evaluation-led design for public value and client trust Managing the Total Customer Experience Small business digital transformation in the context of the pandemic Impact of customer experience on loyalty a multichannel examination Customer experience – a review and research agenda Towards a unified customer experience in online shopping environments Customer experience management in hospitality: a literature synthesis, new understanding, and research agenda
A8: Questão central de pesquisa: | B8: Total experience: Como o design dirigido ao cliente está impactando os processos dos produtos/serviços no varejo online?
A9: Questões secundárias: | B9: Q1 - O estudo define os componentes do total experience? Se sim, como? Q2 - Como total experience é aplicada nas organizações atuais? Q3 - Quais são os principais impactos(Pessoas, tecnologias e processos) da total experience nos serviços/produtos, de acordo com os estudos encontrados? Q4 - Qual são as principais funções que as mídias sociais oferecem para a total experience?
A10: Método: | B10: Revisão
A11: RESULTADO ESPERADO PARTE 1: | B11: Planejamento da pesquisa, definindo tema, objetivos, motivação, questões de pesquisa, fundamentados por ao menos 2 artigos de referência.
A12: Parte 2: Protocolo de Pesquisa
A13: Palavras-chave: | B13: total experience, online retail, customer
A14: Sinônimos por palavras-chave: | B14: total experience or multiexperience or user experience or customer experience , online retail or e-commerce or eletronic commerce, customer or client or user
A15: String de busca: | B15: ( "total experience" OR multiexperience OR "user experience" OR "customer experience" ) AND ( "online retail" OR e-commerce OR "eletronic commerce" ) AND ( customer OR client OR user ) ( "total experience" OR multiexperience OR "customer experience" ) AND ( "online retail" OR e-commerce OR "eletronic commerce" ) AND ( customer OR client OR user )
A16: Fontes de pesquisa usadas: | B16: ACM, IEEE Xplore, Scopus e Science Direct
A19: Executar as strings nas bases: | B19: Usar ferramentas de busca automáticas, considerando o período de 2015 a 2020, planilhando os resultados.
A20: Primeiros números por fonte de pesquisa: | B20: Hawaii International Conference on System Sciences 2020 (HICSS-53) - 48 resultados ICIS Proceedings - 76 resultados AMCIS Proceedings - 49 resultados Wirtschaftsinformatik Proceedings - 12 resultados International Conference on Information Systems Development (ISD) - 1 resultado
A21: RESULTADO ESPERADO PARTE 2: | B21: String de busca definida e aplicada nas bases de pesquisa. Se os resultados encontrados estão relacionados com o tema, exportar os resultados para uma planilha para que os filtros da Parte 3 possam ser aplicados.
A22: Parte 3: Definindo e Aplicando Filtros
A23: Critérios de exclusão: | B23: CE01- Artigos que não estejam no período de 2015 a 2020; CE02 - Artigos secundários (outra RSL ou MS); CE03 - Artigos com conteúdo pago; CE04 - Artigos duplicados ou similares; CE05 - Artigos indisponíveis para download ou visualização; CE06 - Artigos que não estejam relacionados com as perguntas de pequisa
A24: Critérios de inclusão: | B24: CI01 - Artigos da base AIS CI02 - Artigos que não estejam relacionados com as perguntas de pesquisa
A25: Filtro 1 (Título e Resumo): | B25: Hawaii International Conference on System Sciences 2020 (HICSS-53) - 5 resultados ICIS Proceedings - 8 resultados AMCIS Proceedings - 9 resultados
A26: Filtro 2 (Introdução e Conclusão): | B26: Informar o número de artigos por cada base, após a aplicação do filtro verificando a introdução e conclusão do artigo. Obs: o filtro 2 só é usado caso você não consiga decidir se o artigo é válido ou não usando o filtro 1.
A27: Como os critérios serão aplicados? | B27: Os critérios de exclusão foram aplicados com base no título e resumo (analisando os dados das perguntas de 1 a 5 e utilizando as palavras chaves e conceitos para validar o critério 6) O critério de inclusão 1 foi automatica aprovado em todos, mas com base no critério 6 automaticamente é selecionado ou não.
A28: RESULTADO ESPERADO PARTE 3: | B28: Planilha com a lista de estudos. Os títulos que passaram pelo filtro 1 devem ser pintados de verde, os em dúvida pintados de amarelo e os que não passaram em vermelho. Sinalizar qual o filtro usado para os vermelhos. Os estudos em amarelo deverão passar pelo filtro 2, tornando-se verde ou vermelho.
A29: Parte 4: Qualificando os Estudos
A30: Critérios de qualidade: | B30: Contexto Claro, Metodologia bem definida, Aplicação Prática, Discussão relevantes e consistentes e Limitações e ameaças da pesquisa comentadas
A31: Como os critérios serão aplicados? | B31: Analisar atráves dos critérios de qualidade se o artigo atende ou não as necessidades da nossa qualificação.
A32: RESULTADO ESPERADO PARTE 4: | B32: Planilha com a lista de estudos pintados de verde, acrescentando colunas com os critérios de qualidade. Cada estudo deverá ter uma "nota de qualidade", somando as notas de cada critério. Para valorar o critérios usar a seguinte escala: "0 - não tende; 0.5 - atende parcialmente; 1.0 - atendente totalmente".
A33: Parte 5: Seleção de Artigos
A34: Artigos selecionados por fonte: | B34: Hawaii International Conference on System Sciences 2020 (HICSS-53) - 4 resultados ICIS Proceedings - 7 resultados AMCIS Proceedings - 5 resultados
A35: Artigos selecionados para análise: | B35: Does Being Reputable Drive Customer Equity? Evidence from E-Commerce Web Experience and Growth User Experience in Personalized E-Commerce: A Configurational Approach Biases in Social Commerce Users' Rational Risk Considerations Exploring Trust and Enjoyment in Social Commerce: A Cross-Cultural Research Proposal Contemporary Micro-IT Capabilities and Organizational Performance: The Role of Online Customer Engagement E-Services: An Experience Centric Perspective Deal or No Deal? - Asessing the Daily Deal Shopper Customer Attitude from Social Media, Customer Satisfaction Index, and Firm Value Online Search Behavior in the Air Travel Market: Reconsidering the Consideration Set and Customer Journey Concepts Employing Mixed Reality Applications: Customer Experience Perspective Digital Transformation: Of Paradoxical Tensions and Managerial Responses Towards Developing Trust-Supporting Design Features for AI-Based Chatbots in Customer Service Conversational Agents - Exploring Generative Mechanisms and Second-hand Effects of Actualized Technology Affordances A Mixed Method Approach to Understanding Crowdsourcees’ Engagement Behavior
A36: RESULTADO ESPERADO PARTE 5: | B36: Planilha com a lista de estudos qualificados, com suas respectivas notas de qualidade. Os estudos com notas iguais ou superior a 50% da maior nota e qualidade deverão ser selecionados para a lista final de artigos, ordenada pelo ano de publicação.
A37: Parte 6: Coleta de Evidências
A38: Critérios de responsividade: | B38: 1- Responde, 0.5- Responde parcialmente e 0 - Não
A39: Respostas às questões de pesquisa: | B39: Link para planilha de respostas, informando para cada artigo, qual a questão que ele responde, de acordo com os critérios de responsividade. Não esquecer de guardar evidências das respostas (trecho do artigo).
A40: RESULTADO ESPERADO PARTE 6: | B40: Planilha com a lista finais selecionados, incluindo as colunas com as questões de pesquisa. Para cada questão buscar nos estudo trechos do artigo que respondem a questão.
A41: Parte 7: Análise & Síntese de Dados
A42: Respondendo questões de pesquisa: | B42: Selecionar palavras-chaves (tags) dos trechos selecionados como resposta das questões de pesquisa. Consolidar as respostas a partir destas palavras-chaves. Verificar softwares que possam ajudar nisso.
...

Sheet Exemplo 2 - Internet of Behavio
A1: TENDÊNCIAS E DESAFIOS EM SI - ESTRUTURAÇÃO DA INVESTIGAÇÃO SISTEMÁTICA
A2: Parte 1: Planejamento
A3: Integrantes do time:
A4: Tema de pesquisa: | B4: Serviços Baseados em IoT a partir da coleta dos dados pessoais.
A5: Objetivos da pesquisa: | B5: Investigar a influência da coleta dos dados pessoais nos serviços de saúde baseados em IoT. Verificar o impacto dos serviços baseados em IoT na saúde das pessoas.
A6: Motivação/Justificativa: | B6: Este assunto é relevante pois segundo Gartner até 2020 já teríamos a tecnologia de IoT em 95% dos eletrônicos. Soluções desenvolvidas em IoT têm contribuído para avanços na área de saúde. Os dispositivos IoT permitem a coleta de dados em grande volume, online e em tempo real.
A7: Artigos referência (título e link): | B7: http://clyde.dr.ufu.br/bitstream/123456789/24847/3/EstudoAplicacaoSistema.pdf https://revista.fatectq.edu.br/index.php/interfacetecnologica/article/view/515/304 https://lcv.fee.unicamp.br/images/BTSym-17/Papers/72535.pdf https://nvlpubs.nist.gov/nistpubs/ir/2021/NIST.IR.8228pt.pdf https://sci-hub.se/https://ieeexplore.ieee.org/abstract/document/8423891 https://sci-hub.se/https://www.sciencedirect.com/science/article/abs/pii/S0167739X17314127
A8: Questão central de pesquisa: | B8: Como as soluções utilizando IoT estão sendo aplicadas na saúde das pessoas?
A9: Questões secundárias: | B9: Q1 - Quais as tecnologias de IoT estão sendo usadas? Q2 - Que tipo de serviço está sendo utilizado? Q3 - Quais dados estão sendo coletados? Q4 - Qual impacto na saúde das pessoas?
A10: Método: | B10: Revisão.
A11: RESULTADO ESPERADO PARTE 1: | B11: Planejamento da pesquisa, definindo tema, objetivos, motivação, questões de pesquisa, fundamentados por ao menos 2 artigos de referência.
A12: Parte 2: Protocolo de Pesquisa
A13: Palavras-chave: | B13: 1 - Internet of Things 2 - Healthcare 3 - Medicine
A14: Sinônimos por palavras-chave: | B14: Internet of Things - IoT Healthcare - Health- Personal Health Medicine - Preventive Medicine
A15: String de busca: | B15: V1 - (Internet of Things OR IoT) AND (Internet of Behaviors OR IoB) AND (Healthcare OR Preventive Medicine OR Preventive Care OR Personal Health) AND (Big Data Analytics OR Analytics OR Data Analysis) V2 - (Internet of Things OR IoT) AND (Internet of Behaviors OR IoB) AND (Healthcare OR Preventive Medicine OR Preventive Care OR Personal Health) AND (Big Data Analytics OR Data Analysis) V3 - (Internet of Things OR IoT) AND (Internet of Behaviors OR IoB) AND (Healthcare OR Preventive Medicine OR Personal Health) AND (Big Data Analytics OR Data Analysis) V4 - (Internet of Things OR IoT) AND (Internet of Behaviors OR IoB) AND (Healthcare OR Preventive Medicine OR Personal Health) AND (Data Analysis) V5 - (Internet of Things OR IoT) AND (Internet of Behaviors OR IoB) AND (Healthcare OR Preventive Medicine OR Personal Health) AND (Big Data Analytics OR Data Analysis) String Final: ( "Internet of Things" OR IoT ) AND ( "Personal Health" OR Health OR Healthcare ) AND ( Medicine OR "Preventive Medicine" )
A16: Fontes de pesquisa usadas: | B16: ACM, IEEE Xplore, Scopus e Science Direct
A19: Executar as strings nas bases: | B19: https://docs.google.com/spreadsheets/d/10V3_Zgbui7HD5bgSpMVfZfrSk2H8XOczcJvvSw-eSm4/edit#gid=1546267202
A20: Primeiros números por fonte de pesquisa: | B20: AMCIS Proceedings - 24 artigos Hawaii International Conference on System Sciences (HICSS) - 42 artigos ICIS Proceedings - 17 artigos International Conference on Information Systems Development (ISD) - 04 artigos Wirtschaftsinformatik Proceedings - 01 artigo Total de 88 artigos encontrados
A21: RESULTADO ESPERADO PARTE 2: | B21: String de busca definida e aplicada nas bases de pesquisa. Se os resultados encontrados estão relacionados com o tema, exportar os resultados para uma planilha para que os filtros da Parte 3 possam ser aplicados.
A22: Parte 3: Definindo e Aplicando Filtros
A23: Critérios de exclusão: | B23: - Artigos não relacionados ao tema e perguntas da pesquisa - Artigos fora do período da pesquisa (2015 à 2020) - Artigos indisponíveis para visualização - Artigos com conteúdos pagos
A24: Critérios de inclusão: | B24: - Artigos da base AIS - Artigos relacionados ao tema e perguntas da pesquisa - Artigos completos
A25: Filtro 1 (Título e Resumo): | B25: AMCIS Proceedings - 10 artigos Hawaii International Conference on System Sciences (HICSS) - 24 artigos ICIS Proceedings - 06 artigos International Conference on Information Systems Development (ISD) - 02 artigos Total de 42 artigos encontrados
A26: Filtro 2 (Introdução e Conclusão): | B26: AMCIS Proceedings - 03 artigos Hawaii International Conference on System Sciences (HICSS) - 10 artigos ICIS Proceedings - 02 artigos Total de 15 artigos encontrados
A27: Como os critérios serão aplicados? | B27: Durante a pesquisa, utilizamos a ferramenta da base AIS, selecionando assim, apenas artigos da própria base de dados, aplicamos então o filtro de data, excluíndo os artigos fora do período da pesquisa, em seguida tabulamos os resultados e fizemos uma análise individual avaliando os critérios de inclusão e exclusão, primeiramente selecionamos os artigos relacionados ao tema e perguntas da pesquisa, excluindo assim os artigos sem relação com o tema, em seguida utilizamos o título e resumo como como filtro inicial e verificamos as introduções e conclusões dos artigos como segundo filtro, durante o processo de análise podemos avaliar quais artigos possuíam conteúdo pago ou estavam indisponíveis para visualização, os excluíndo assim do processo.
A28: RESULTADO ESPERADO PARTE 3: | B28: Planilha com a lista de estudos. Os títulos que passaram pelo filtro 1 devem ser pintados de verde, os em dúvida pintados de amarelo e os que não passaram em vermelho. Sinalizar qual o filtro usado para os vermelhos. Os estudos em amarelo deverão passar pelo filtro 2, tornando-se verde ou vermelho.
A29: Parte 4: Qualificando os Estudos
A30: Critérios de qualidade: | B30: - Contexto claro - Metodologia bem definida - Proposta bem apresentada - Aplicação prática - Discussões relevantes e consistentes - Limitações e ameaças da pesquisa selecionada.
A31: Como os critérios serão aplicados? | B31: Foram distribuídos os 15 artigos filtrados na Parte 3 entre os membros da equipe, para leitura e análise em concordância com os critérios estabelecidos, sendo atribuídas pontuações de acordo com a escala pré-definida.
A32: RESULTADO ESPERADO PARTE 4: | B32: Planilha com a lista de estudos pintados de verde, acrescentando colunas com os critérios de qualidade. Cada estudo deverá ter uma "nota de qualidade", somando as notas de cada critério. Para valorar o critérios usar a seguinte escala: "0 - não tende; 0.5 - atende parcialmente; 1.0 - atendente totalmente".
A33: Parte 5: Seleção de Artigos
A34: Artigos selecionados por fonte: | B34: AMCIS Proceedings - 02 artigos Hawaii International Conference on System Sciences (HICSS) - 09 artigos ICIS Proceedings - 02 artigos Total de 13 artigos selecionados
A35: Artigos selecionados para análise: | B35: https://docs.google.com/spreadsheets/d/1FeaD2UoM5sB2fkhJYgRnT_PjjyTy7EzvOzXjL8T54Wo/edit#gid=711724059
A36: RESULTADO ESPERADO PARTE 5: | B36: Planilha com a lista de estudos qualificados, com suas respectivas notas de qualidade. Os estudos com notas iguais ou superior a 50% da maior nota e qualidade deverão ser selecionados para a lista final de artigos, ordenada pelo ano de publicação.
A37: Parte 6: Coleta de Evidências
A38: Critérios de responsividade: | B38: Definir critérios para classificação de respostas às perguntas de pesquisa, com escala de valor a sua escolha. Por exemplo, 1- Repsponde, 0.5- Responde parcialmente e 0 - Não responde. Ver exemplos nos artigos do drive da disciplina.
A39: Respostas às questões de pesquisa: | B39: https://docs.google.com/spreadsheets/d/1FeaD2UoM5sB2fkhJYgRnT_PjjyTy7EzvOzXjL8T54Wo/edit#gid=711724059
A40: RESULTADO ESPERADO PARTE 6: | B40: Planilha com a lista finais selecionados, incluindo as colunas com as questões de pesquisa. Para cada questão buscar nos estudo trechos do artigo que respondem a questão.
A41: Parte 7: Análise & Síntese de Dados
A42: Respondendo questões de pesquisa: | B42: Selecionar palavras-chaves (tags) dos trechos selecionados como resposta das questões de pesquisa. Consolidar as respostas a partir destas palavras-chaves. Verificar softwares que possam ajudar nisso.
...

Sheet Cópia de Template RSL
A1: Prompt | AA1: //
A2: Parte 2: Protocolo de Pesquisa
A3: Palavras-chave: | B3: AI Agents, Customer Service, Service Automation, Decision Making
A4: Sinônimos por palavras-chave: | B4: Agentes de IA: agentes inteligentes, sistemas autônomos, agentes cognitivos, agentes de software Atendimento ao cliente: Customer Experience, Central de Serviços, Operações de Contact Center Automação de serviços: Automação Inteligente, Otimização de Processos, Automação Robótica de Processos (RPA), Automação de tarefas, Tomada de Decisão: Suporte a decisão
A5: String de busca: | B5: ("AI agents" OR "intelligent agents" OR "cognitive agents" OR "intelligent Agents" OR "autonomous Systems" OR "software Agents") AND ("customer service" OR "customer experience" OR "service center" OR " contact center operations") AND ( "services automation" OR "intelligent automation" OR "smart automation" OR "process optimization" OR "robotic process automation" OR "task automation") AND ("decision making" OR "decision support")
A6: Fontes de pesquisa usadas: | B6: > The influence of artificial intelligence chatbot problem solving on customers’ continued usage intention in e-commerce platforms: an expectation-confirmation model approach > The Art of Talking Machines: A Comprehensive Literature Review of Conversational User Interfaces > From Decision Support to Decision Making: Autonomous AI Agents Shaping the Marketing > AI-driven nudges: Influence of chatbot personas on consumer food choices
A7: Executar a string de busca nas bases: | B7: > ACM > IEEE > Scopus
A8: Primeiros números por fonte de pesquisa: | B8: Para cada base (ou conferência), listar o número de artigos encontrados.
B9: ACM | C9: 178 | D9: https://dl.acm.org/action/doSearch?fillQuickSearch=false&target=advanced&expand=dl&AllField=AllField%3A%28"AI+agents"+OR+"intelligent+agents"+OR+"cognitive+agents"+OR+"autonomous+systems"+OR+"software+agents"%29+AND+AllField%3A%28"customer+service"+OR+"customer+experience"+OR+"contact+center+operations"%29+AND+AllField%3A%28"services+automation"+OR+"intelligent+automation"+OR+"smart+automation"+OR+"process+optimization"+OR+"robotic+process+automation"+OR+"task+automation"%29+AND+AllField%3A%28"decision+making"+OR+"decision+support"%29&AfterYear=2020&BeforeYear=2025&queryID=13%2F9832995874
B10: IEEE | C10: 26 | D10: https://ieeexplore.ieee.org/search/searchresult.jsp?action=search&matchBoolean=true&queryText=(%22All%20Metadata%22:%22AI%20agents%22%20OR%20%22All%20Metadata%22:%22intelligent%20agents%22%20OR%20%22All%20Metadata%22:%22cognitive%20agents%22%20OR%20%22All%20Metadata%22:%22intelligent%20Agents%22%20%20%22autonomous%20Systems%22%20OR.%20%22software%20Agents%22)%20AND%20(%22All%20Metadata%22:%22customer%20service%22%20OR%20%22All%20Metadata%22:%22customer%20experience%22%20OR%20%22All%20Metadata%22:%22central%20de%20servi%C3%A7os%22%20OR%20%22All%20Metadata%22:%22%20contact%20center%20operations%22)%20AND%20(%22All%20Metadata%22:%22Services%20Automation%22%20OR%20%22All%20Metadata%22:%22intelligent%20automation%22%20OR%20%22All%20Metadata%22:%22Smart%20Automation%22%20OR%20%22All%20Metadata%22:%22process%20optimization%22%20OR%20%22All%20Metadata%22:%22robotic%20process%20automation%22%20OR%20%22All%20Metadata%22:%22Task%20Automation%22)%20AND%20(%22All%20Metadata%22:%22Decision%20Making%22%20OR%20%22All%20Metadata%22:%20Decision%20Support%22)&highlight=true&returnType=SEARCH&matchPubs=true&returnFacets=ALL&ranges=2020_2025_Year
B11: Scopus | C11: 226 | D11: https://www.scopus.com/results/results.uri?sort=plf-f&src=s&sid=b60ecc03b8d49e9753ad00f56367fbe4&sot=a&sdt=cl&sl=442&s=%28%22AI+agents%22+OR+%22intelligent+agents%22+OR+%22cognitive+agents%22+OR+%22intelligent+Agents%22+OR+%22autonomous+Systems%22+OR+%22software+Agents%22%29+AND+%28%22customer+service%22+OR+%22customer+experience%22+OR+%22central+de+servi%26%23231%3Bos%22+OR+%22contact+center+operations%22%29+AND+%28%22Services+Automation%22+OR+%22intelligent+automation%22+OR+%22Smart+Automation%22+OR+%22process+optimization%22+OR+%22robotic+process+automation%22+OR+%22Task+Automation%22%29+AND+%28%22Decision+Making%22+OR+%22Decision+Support%22%29&origin=resultslist&editSaveSearch=&txGid=4dfd1e4cdeda15c322ca2696a13e3c1e&sessionSearchId=b60ecc03b8d49e9753ad00f56367fbe4&limit=10&yearFrom=2020&yearTo=2025
B12: Total de Artigos | C12: =SUM(C9:C11) -> 430
A13: Critérios de inclusão: | B13: 1. Investigate the use of AI agents (such as LLMs, multi-agent systems, or reinforcement learning) applied to decision-making or task automation in organizational contexts. 2. Address customer service operations, process automation, or business decision support. 3. Present empirical or experimental evidence, or case studies, on the implementation or impact of these agents. 4. Be available in full text, written in English or Portuguese.
A14: Critérios de exclusão: | B14: 1. Articles that do not directly address AI agents focused on decision-making, organizational automation, or decision support in organizational contexts. 2. Articles without full-text access, either due to lack of open access or unavailability via institutional credentials. 3. Articles published before 2020 . 4. Duplicate records found in different databases or multiple versions of the same study. 5. Short papers or summarized formats, including extended abstracts, posters, short reports, or articles with less than 6 pages of main content.
A15: RESULTADO ESPERADO PARTE 2: | B15: String de busca definida e aplicada nas bases de pesquisa. Se os resultados encontrados estão relacionados com o tema, exportar os resultados para uma planilha para que os filtros da Parte 3 possam ser aplicados.
G56: =450.897777777777 -> 450.89778
G57: /

Sheet Registro de Uso da IA p3
A1: Prompt | C1: System prompt: Assume you are an expert professor in Software Engineering conducting a systematic literature review. Your task is to evaluate studies based on specific criteria: Inclusion Criteria (IC): 1. Investigate the use of AI agents (such as LLMs, multi-agent systems, or reinforcement learning) applied to decision-making or task automation in organizational contexts. 2. Address customer service operations, process automation, or business decision support. 3. Present empirical or experimental evidence, or case studies, on the implementation or impact of these agents. 4. Be available in full text, written in English or Portuguese. Exclusion Criteria (EC): Exclusion criteria from primary candidate study 1. Articles that do not directly address AI agents focused on decision-making, organizational automation, or decision support in organizational contexts. 2. Articles without full-text access, either due to lack of open access or unavailability via institutional credentials. 3. Articles published before 2020 . 4. Duplicate records found in different databases or multiple versions of the same study. 5. Short papers or summarized formats, including extended abstracts, posters, short reports, or articles with less than 6 pages of main content. For scoring, use only 1 or 0: Assign a score of 1 for strong alignment with all inclusion criteria. Assign a score of 0 if any inclusion criteria are not satisfied or if any exclusion criteria are met. You’ll score studies based on their title and abstracts. For the response, use the following format: Response Format: Begin with ‘‘Score: X’’ followed by ‘‘Justification:’’ that explains why the study was considered relevant or not. User prompt: Title: Title of a primary candidate study Abstract: abstract of a primary candidate study
A2: LLM1: CHATGPT | C2: 5.O
A3: LLM2: GEMINI | C3: 2.5 PRO
A4: Base de Dados | B4: Autor(es) | C4: Título do artigo | D4: Ano | E4: URL / DOI | F4: Resumo (abstract) | G4: Palavras-chave principais | H4: Relevância segundo LLM 1 (Sim/Não) | I4: Relevância segundo LLM 2 (Sim/Não) | J4: Diferença entre LLM 1 e LLM 2 | K4: Justificativa da LLM 1 | L4: Justificativa da LLM 2 | M4: LLM que apresentou melhor justificativa (1 ou 2) | N4: Artigo selecionado para a próxima fase
A5: ACM | B5: Mohammad (Matt) Namvarpour, Afsaneh Razi | C5: The Art of Talking Machines: A Comprehensive Literature Review of Conversational User Interfaces | D5: 2025 | E5: https://doi.org/10.1145/3719160.3736621 | F5: This article offers a comprehensive review of Conversational User Interfaces (CUIs), addressing the areas of interface design, systems development, and ethical considerations. The study highlights advancements and challenges in CUIs, such as conversation memory, multimodal interaction, and ethical considerations, as well as suggesting future directions for research. | G5: Conversational User Interfaces, CUI, Revisão de Literatura, Design de Interfaces, Processamento de Linguagem Natural, Ética | H5: Sim | I5: Não | J5: =IF(OR(ISBLANK(H5),ISBLANK(I5)),"",IF(H5<>I5,"Diferente","Igual")) -> Diferente | K5: The study aligns with the inclusion criteria, especially in terms of investigating AI technologies used in task automation and decision support systems. It provides valuable insights into the design, development, and ethical considerations in CUIs, which are related to the task automation in organizational contexts. However, it does not present original empirical evidence, but since it's a comprehensive literature review, it still meets the inclusion criteria. | L5: The article's title and abstract clearly state that it is a "Comprehensive Literature Review" of Conversational User Interfaces (CUIs). A literature review is a form of secondary research that synthesizes the work of others (279 publications in this case ). It does not present new, primary empirical or experimental evidence or a case study of a deployed AI agent, which is a mandatory requirement for inclusion. | M5: LLM 1 | N5: =IF(OR(ISBLANK(H5),ISBLANK(I5)),"", IF(J5="Diferente","Sim",IF(H5="Sim","Sim","Não"))) -> Sim | P5: Mateus
A6: Scopus | B6: Junzhe Gao , Abdullah Promise Opute , Caroline Jawad , Meng Zhan | C6: The influence of artificial intelligence chatbot problem solving on customers’ continued usage intention in e-commerce platforms: an expectation-confirmation model approach | D6: 2025 | E6: https://www.sciencedirect.com/science/article/pii/S0148296325004849?pes=vor&utm_source=scopus&getft_integrator=scopus | F6: The rapid advancement of artificial intelligence (AI) technology has led to its widespread application across various fields, including e-commerce platforms. AI chatbots, powered by large data models, have emerged as a crucial tool for enhancing customer service and user experience. This study aims to investigate the impact of AI chatbot problem-solving capabilities on users’ intention to continue using these services within e-commerce platforms. By integrating elements from the Expectation-Confirmation Model (ECM) and the Technology Acceptance Model (TAM), a comprehensive research model is proposed to examine the relationships between problem-solving, confirmation, perceived ease of use, satisfaction, trust, and continued usage intention. The study employs structural equation modelling (SEM) to analyse data collected from 315 participants through an online questionnaire. The findings reveal that problem-solving abilities positively influence users’ confirmation, which in turn positively affects satisfaction, perceived ease of use, and trust. Furthermore, perceived ease of use exhibits a positive impact on satisfaction, trust, and continued usage intention. Satisfaction and trust have a positive impact on continued usage intention, with satisfaction showing a stronger influence than both problemsolving ability and ease of use. The study contributes to the theoretical understanding of user perceptions and behaviours in AI-driven interactions within e-commerce platforms. It highlights the importance of problemsolving capabilities, perceived ease of use, satisfaction, and trust in driving users’ continued engagement with AI chatbots. Practical implications for AI technology developers and e-commerce companies are discussed, emphasizing the need to focus on enhancing chatbots’ problem-solving proficiency and user-friendliness to foster long-term user retention. Future research directions are proposed, addressing the study’s limitations and exploring the generalizability of the findings beyond the e-commerce context. | G6: AI chatbots E-commerce Problem-solving Expectation-confirmation model Technology acceptance model | H6: Sim | I6: Sim | J6: =IF(OR(ISBLANK(H6),ISBLANK(I6)),"",IF(H6<>I6,"Diferente","Igual")) -> Igual | K6: Score 1 Este artigo investiga a influência das capacidades de resolução de problemas de chatbots de IA no comportamento de uso contínuo dos clientes em plataformas de e-commerce. O estudo foca em como essas capacidades impactam a satisfação, confiança, facilidade de uso percebida e a intenção de continuar usando esses serviços, utilizando um modelo integrado baseado no Modelo de Expectativa-Confirmação (ECM) e no Modelo de Aceitação de Tecnologia (TAM). A pesquisa empírica foi realizada por meio de um modelo de equações estruturais (SEM) com dados de 315 participantes, analisando variáveis como confirmação das expectativas, satisfação, confiança e a facilidade de uso percebida dos chatbots em e-commerce. Pontos principais: Capacidade de resolução de problemas dos chatbots é vista como fundamental para aumentar a intenção de uso contínuo. Satisfação e confiança têm um impacto direto na intenção de continuar o uso do chatbot. A facilidade de uso percebida é um fator significativo que afeta a satisfação e a confiança do usuário, influenciando diretamente sua intenção de continuar utilizando a plataforma. O estudo contribui teoricamente para a compreensão do comportamento do usuário ao interagir com chatbots de IA em plataformas de e-commerce, fornecendo insights sobre o impacto das capacidades de resolução de problemas na satisfação e no engajamento do cliente. Relevância para os critérios de inclusão: Uso de IA aplicada à tomada de decisão e automação de tarefas - O artigo investiga chatbots baseados em IA, focando na resolução de problemas em e-commerce, que é diretamente relacionado à automação de processos de atendimento ao cliente. Atendimento ao cliente e automação de processos - O estudo aborda como os chatbots de IA melhoram o atendimento ao cliente e a experiência do usuário, alinhando-se diretamente a este critério. Evidências empíricas - O estudo utiliza modelagem de equações estruturais (SEM) com dados empíricos, validando o impacto das capacidades dos chatbots no comportamento do consumidor. Disponibilidade em texto completo e em inglês - O artigo está disponível em texto completo e foi escrito em inglês, atendendo ao critério de idioma e acessibilidade. Conclusão: O artigo atende a todos os critérios de inclusão e não apresenta critérios de exclusão que o invalidem. Portanto, ele deve ser selecionado para a próxima fase. | L6: Score: 1 Justification: The study strongly aligns with all inclusion criteria and does not meet any exclusion criteria. IC 1 (AI agents in organizational context): Satisfied. The study investigates "Al chatbots" (an AI agent, specifically noted as "powered by large data models" ) applied within "e-commerce platforms" (an organizational context). IC 2 (Customer service/automation): Satisfied. The abstract explicitly states the focus is on AI chatbots as a "crucial tool for enhancing customer service". IC 3 (Empirical evidence): Satisfied. The abstract details the methodology, stating the "study employs structural equation modelling (SEM) to analyse data collected from 315 participants". IC 4 (Full text/language): Satisfied. The full text is available and written in English. EC 3 (Publication date): Not Met. The article is published in 2025, which is within the required 2020-2025 window. EC 5 (Page length): Not Met. The article is 14 pages long, which is well over the 6-page minimum. | M6: LLM 1 | N6: =IF(OR(ISBLANK(H6),ISBLANK(I6)),"", IF(J6="Diferente","Sim",IF(H6="Sim","Sim","Não"))) -> Sim
A7: IEEE | B7: Sahar Mirzayi, Erfan Talajouran | C7: From Decision Support to Decision Making: Autonomous AI Agents Shaping the Marketing | D7: 2025 | E7: https://ieeexplore.ieee.org/document/11006187 | F7: As artificial intelligence (AI) increasingly drives marketing decisions, understanding its shift from decision support to full autonomy is essential for academia and industry. This paper addresses this gap by analyzing AI's transformative impact on marketing through the lens of the 7Ps framework (Product, Price, Place, Promotion, People, Process, and Physical Evidence). By categorizing AI's role at various levels of autonomy, the study highlights the substantial influence of AI-driven agents, particularly within the Process and Promotion elements where automation has evolved into intelligent decision-making. This research offers a foundational framework for understanding AI autonomy in marketing, providing valuable insights for future marketing strategies. | G7: AI Marketing, Marketing Automation, Autonomous Agents, 7Ps Framework, Decision Making, Decision Support Systems. | H7: Sim | I7: Não | J7: =IF(OR(ISBLANK(H7),ISBLANK(I7)),"",IF(H7<>I7,"Diferente","Igual")) -> Diferente | K7: Score: 1 Justification: Este artigo atende a todos os critérios de inclusão e não viola nenhum critério de exclusão: Investigação do uso de IA aplicada à decisão ou automação em contextos organizacionais O artigo explora a transição da IA de suporte à decisão para tomada de decisão autônoma em marketing, especificamente em e-commerce, o que se alinha diretamente ao critério de aplicação da IA para tomada de decisão e automação de tarefas. Abordar operações de atendimento ao cliente, automação de processos, ou suporte à decisão empresarial O estudo aborda como agentes de IA, como chatbots e sistemas de recomendação, são utilizados para automatizar e otimizar processos de marketing, especialmente nas áreas de promoção e processos, claramente relevantes para o critério. Apresentar evidências empíricas, experimentais ou estudos de caso sobre a implementação ou impacto desses agentes O estudo apresenta uma análise qualitativa baseada em revisão de literatura e exemplos de implementação prática de IA em marketing, discutindo como essas ferramentas impactam estratégias de marketing. Embora não sejam estudos de caso extensivos, o artigo baseia-se em dados práticos e exemplifica o uso real de IA no setor, o que satisfaz parcialmente este critério. Estar disponível em texto completo, escrito em inglês ou português O artigo está disponível em texto completo, em inglês, atendendo a este critério. Além disso, o artigo não se encaixa em nenhuma das categorias de exclusão: Não trata de IA em áreas não relacionadas a decisão ou automação organizacional. Está disponível em texto completo. Não é uma publicação anterior a 2020. Não é um artigo duplicado ou de formato resumido (ex: resumo ou poster). Conclusão: O artigo cumpre os critérios de inclusão e não infringe os critérios de exclusão, sendo aprovado com nota 1. | L7: Score: 0 Justificação: O estudo não atende a todos os critérios de inclusão. Embora o artigo investigue o uso de agentes autônomos de IA (IC 1) aplicados à tomada de decisão e automação de processos no contexto organizacional de marketing (IC 2) , e cumpra os critérios de data (publicado em 2025) e idioma (EC 3, IC 4), ele não satisfaz o Critério de Inclusão 3. O IC 3 exige que o estudo "apresente evidências empíricas ou experimentais, ou estudos de caso". Este artigo é explicitamente uma "revisão narrativa da literatura" e uma proposta de framework teórico. Embora analise "implementações de IA do mundo real" como exemplos para construir seu framework, o estudo em si não é um estudo de caso primário, um experimento ou uma coleta de dados empíricos originais. Sua metodologia é uma revisão qualitativa e exploratória da literatura e de casos públicos. | M7: LLM 1 | N7: =IF(OR(ISBLANK(H7),ISBLANK(I7)),"", IF(J7="Diferente","Sim",IF(H7="Sim","Sim","Não"))) -> Sim
A8: Scopus | B8: Xiyu Guo , Xiaoang Wan | C8: AI-driven nudges: Influence of chatbot personas on consumer food choices | D8: 2025 | E8: https://www.sciencedirect.com/science/article/pii/S019566632500371X?pes=vor&utm_source=scopus&getft_integrator=scopus | F8: Customized chatbot personas can meet the personalized needs of consumers and enhance user engagement in human-chatbot interactions. We conducted a study to investigate the influence of interacting with a chatbot customized as a health coaching assistant versus a gourmet recommendation assistant on participants’ food choices. Participants were instructed to choose three dishes from a set of two meat and two vegetable options to compose a three-dish meal, both before and after they interacted with the health coaching assistant or the gourmet recommendation assistant. The results revealed a significant decrease in the frequency of meat-heavy meal selections after participants interacted with the health coaching assistant, compared to the gourmet recommendation assistant. These findings suggest that interacting with chatbots tailored as health coaching assistants can effectively nudge consumers toward more sustainable food choices. These findings highlight the potential of human-AI interactions in promoting sustainability and offer implications for the design and implementation of chatbots in the restaurant industry. | G8: Food choice Meat reduction Healthy eating Human-AI interaction Chatbot Persona customization | H8: Sim | I8: Sim | J8: =IF(OR(ISBLANK(H8),ISBLANK(I8)),"",IF(H8<>I8,"Diferente","Igual")) -> Igual | K8: Score: 1 Justification: The study “AI-driven nudges: Influence of chatbot personas on consumer food choices” clearly meets all inclusion criteria (IC) and avoids all exclusion criteria (EC): IC1: It investigates AI agents (chatbots based on LLM-like systems) applied to decision-making in an organizational context (restaurant industry). IC2: It addresses customer service operations and business decision support, analyzing how chatbots influence customer choices and potentially enhance service performance in restaurants. IC3: It presents empirical experimental evidence, with controlled tests examining the behavioral impact of chatbot personas on food choices. IC4: The paper is a full-text, peer-reviewed article in English, published in 2025. None of the exclusion criteria (EC) apply: It directly addresses AI agents for decision support and automation. It is fully accessible via institutional and open-access sources. It was published after 2020 (2025). It is not a duplicate, short paper, or abstract-only submission. Hence, the study strongly aligns with the inclusion scope for AI agent applications in decision-making and automation within organizational contexts. | L8: Score: 1 Justification: The study strongly aligns with all inclusion criteria and does not meet any exclusion criteria. IC 1 (AI agents in organizational context): Satisfied. The abstract investigates "chatbots" (AI agents) customized with specific personas to influence "consumer food choices" (decision-making) in the "restaurant industry" (organizational context). IC 2 (Customer service/automation): Satisfied. The study addresses the use of chatbots as a "health coaching assistant" or "gourmet recommendation assistant" , which are forms of customer service and business decision support (by "nudge[ing] consumers"). IC 3 (Empirical evidence): Satisfied. The abstract describes an experimental study where participants made choices "before and after they interacted with the... assistant" , and "The results revealed a significant decrease", presenting clear empirical evidence. IC 4 (Full text/language): Satisfied. The full text is available and is written in English. EC 3 (Publication date): Not Met. The article is published in 2025, which falls within the required 2020-2025 timeframe. EC 5 (Page length): Not Met. The article is 9 pages long, exceeding the 6-page minimum. | M8: LLM 1 | N8: =IF(OR(ISBLANK(H8),ISBLANK(I8)),"", IF(J8="Diferente","Sim",IF(H8="Sim","Sim","Não"))) -> Sim
J9: =IF(OR(ISBLANK(H9),ISBLANK(I9)),"",IF(H9<>I9,"Diferente","Igual")) | N9: =IF(OR(ISBLANK(H9),ISBLANK(I9)),"", IF(J9="Diferente","Sim",IF(H9="Sim","Sim","Não")))
A10: ACM | B10: Modlinski, Artur and Kedziora, Damian and Hak, Andrzej and Motylewski, Jaroslaw and Kedziora, Joanna and Reijers, Hajo A. and del-R\'{\i | C10: Techno-empowerment of&nbsp;Process Automation: Understanding Employee Acceptance of&nbsp;Autonomous AI in&nbsp;Business Processes | D10: 2024 | E10: 10.1007/978-3-031-70396-6_29 | F10: Research in domains such as the car industry and banking has shown people’s acceptance of techno-empowerment, the phenomenon of entrusting technologies with autonomous decision making. An open question is whether process participants are inclined to transfer their decision-making autonomy to software that they are already familiar with yet is extended with AI capabilities. This paper reports on a study carried out to investigate this question by emulating the imminent organizational introduction of techno-empowered, AI-enhanced Robotic Process Automation (RPA). It involved 126 employees within four international companies residing in Poland that had already been routinely applying RPA for the automation of parts of their business processes. Our findings demonstrate the moderating role of (1) workplace perceptions and (2) gender on the effect that perceptions participants on currently used RPA software has on shaping their intentions to techno-empower an AI-enhanced RPA system. A follow-up study with managers within these companies shows that these insights are both new and actionable. As such, our findings help managers to improve their understanding of techno-empowerment dynamics, which is conducive to better predict employees’ reactions to techno-empowered RPA and to plan process change more effectively. | G10: Robotic process automation, hyperautomation, autonomous artificial intelligence, techno-empowerment, digital transformation, technology acceptance | H10: Não | I10: Sim | J10: =IF(OR(ISBLANK(H10),ISBLANK(I10)),"",IF(H10<>I10,"Diferente","Igual")) -> Diferente | K10: Excluded: Does not sufficiently meet inclusion criteria (AI agent or empirical organizational focus not evident). | L10: Justification: This study strongly aligns with all inclusion criteria and does not meet any exclusion criteria. IC 1 (AI Agents in Organizational Contexts): Investigates AI-enhanced Robotic Process Automation (RPA), which are autonomous AI systems used for task automation and decision-making in an organizational context (business processes). IC 2 (Organizational Application): Directly addresses process automation in business processes within international companies. IC 3 (Empirical Evidence): Presents empirical evidence via a study involving 126 employees and a follow-up study with managers, investigating employee intentions toward "techno-empowered" AI systems. IC 4 (Full Text/Language): The title and abstract are in English, and it's a full-length article published in a conference proceeding (implied full text). EC 3 (Publication Date): Published in 2024 (after 2020). | M10: LLM 2 | N10: =IF(OR(ISBLANK(H10),ISBLANK(I10)),"", IF(J10="Diferente","Sim",IF(H10="Sim","Sim","Não"))) -> Sim
A11: ACM | B11: Huang, Tian and Yu, Chun and Shi, Weinan and Peng, Zijian and Yang, David and Sun, Weiqi and Shi, Yuanchun | C11: Prompt2Task: Automating UI Tasks on Smartphones from Textual Prompts | D11: 2025 | E11: 10.1145/3716132 | F11: UI task automation enables efficient task execution by simulating human interactions with GUIs, without modifying the existing application code. However, its broader adoption is constrained by the need for expertise in both scripting languages and workflow design. To address this challenge, we present Prompt2Task, a system designed to comprehend various task-related textual prompts (e.g., goals, procedures), thereby generating and performing the corresponding automation tasks. Prompt2Task incorporates a suite of intelligent agents that mimic human cognitive functions, specializing in interpreting user intent, managing external information for task generation, and executing operations on smartphones. The agents can learn from user feedback and continuously improve their performance based on the accumulated knowledge. Experimental results indicated a performance jump from a 22.28% success rate in the baseline to 95.24% with Prompt2Task, requiring an average of 0.69 user interventions for each new task. Prompt2Task presents promising applications in fields such as tutorial creation, smart assistance, and customer service. | G11: UI task automation, UI navigation, natural language, UI understanding, large language models | H11: Não | I11: Sim | J11: =IF(OR(ISBLANK(H11),ISBLANK(I11)),"",IF(H11<>I11,"Diferente","Igual")) -> Diferente | K11: Excluded: Does not sufficiently meet inclusion criteria (AI agent or empirical organizational focus not evident). | L11: Justification: This study strongly aligns with all inclusion criteria and does not meet any exclusion criteria. IC 1 (AI Agents in Organizational Contexts): Describes a system (Prompt2Task) that incorporates a suite of intelligent agents (mimicking human cognitive functions) for task automation driven by Large Language Models (LLMs). IC 2 (Organizational Application): Mentions promising applications in fields such as customer service. IC 3 (Empirical Evidence): Presents experimental results indicating a performance jump and success rate improvement (e.g., from 22.28% to 95.24%), providing quantitative empirical evidence. IC 4 (Full Text/Language): The title and abstract are in English, and it's a full-length article published in a conference proceeding (implied full text). EC 3 (Publication Date): Published in 2025 (after 2020). | M11: LLM 2 | N11: =IF(OR(ISBLANK(H11),ISBLANK(I11)),"", IF(J11="Diferente","Sim",IF(H11="Sim","Sim","Não"))) -> Sim
A12: ACM | B12: Sun, Yu-Zhu and Sun, He-Li and Ma, Jian-Cong and Zhang, Peng and Huang, Xiao-Yong | C12: Multimodal Agent AI: A Survey of Recent Advances and Future Directions | D12: 2025 | E12: 10.1007/s11390-025-4802-8 | F12: In recent years, multimodal agent AI (MAA) has emerged as a pivotal area of research, holding promise for transforming human-machine interaction. Agent AI systems, capable of perceiving and responding to inputs from multiple modalities (e.g., language, vision, audio), have demonstrated remarkable progress in understanding complex environments and executing intricate tasks. This survey comprehensively reviews the state-of-the-art developments in MAA and examines its fundamental concepts, key techniques, and applications across diverse domains. We first introduce the basics of agent AI and its multimodal interaction capabilities. We then delve into the core technologies that enable agents to perform task planning, decision-making, and multi-sensory fusion. Furthermore, we focus on exploring various applications of MAA in robotics, healthcare, gaming, and beyond. Additionally, we mainly focus on analyzing the challenges and limitations of current systems and propose promising research directions for future improvements, including human-AI collaboration, online learning method improvement. By reviewing existing work and highlighting open questions, this survey aims to provide a comprehensive roadmap for researchers and practitioners in the field of MAA. | G12: multimodal agent AI, task planning, decision making, robotic, healthcare | H12: Não | I12: Não | J12: =IF(OR(ISBLANK(H12),ISBLANK(I12)),"",IF(H12<>I12,"Diferente","Igual")) -> Igual | K12: Excluded: Does not sufficiently meet inclusion criteria (AI agent or empirical organizational focus not evident). | L12: Justification: This study is excluded because it fails to satisfy Inclusion Criterion 3 and meets Exclusion Criterion 5. IC 3 (Empirical Evidence): This is a survey ("comprehensively reviews the state-of-the-art developments"), which synthesizes existing research but does not present new empirical or experimental evidence, or case studies of its own on the implementation or impact of the agents. EC 5 (Short Papers/Summarized Formats): Surveys, literature reviews, and roadmaps often fail to meet the "less than 6 pages of main content" criteria or the requirement for presenting primary empirical data (though this is primarily based on the failure of IC 3). The primary reason for exclusion is failure to provide new empirical evidence (IC 3). | M12: LLM 2 | N12: =IF(OR(ISBLANK(H12),ISBLANK(I12)),"", IF(J12="Diferente","Sim",IF(H12="Sim","Sim","Não"))) -> Não
